Workbook
Name BizName: 'SETTINGS'!$B$6
Name OwnerName: 'SETTINGS'!$B$7
Name BizPhone: 'SETTINGS'!$B$8
Name BizEmail: 'SETTINGS'!$B$9
Name BizWeb: 'SETTINGS'!$B$10
Name BizArea: 'SETTINGS'!$B$11
Name AsOfInput: 'SETTINGS'!$B$13
Name AsOf: 'SETTINGS'!$B$14
Name RMInput: 'SETTINGS'!$B$15
Name ReportMonth: 'SETTINGS'!$B$16
Name ReportYear: 'SETTINGS'!$B$17
Name PayRate: 'SETTINGS'!$B$19
Name Burden: 'SETTINGS'!$B$20
Name SupHr: 'SETTINGS'!$B$21
Name MileRate: 'SETTINGS'!$B$22
Name TravelMin: 'SETTINGS'!$B$23
Name FeePct: 'SETTINGS'!$B$24
Name TaxDefault: 'SETTINGS'!$B$25
Name OverheadHr: 'SETTINGS'!$B$26
Name TargetMargin: 'SETTINGS'!$B$28
Name MinJob: 'SETTINGS'!$B$29
Name SoonDays: 'SETTINGS'!$B$30
Name ReactDays: 'SETTINGS'!$B$31
Name QCPass: 'SETTINGS'!$B$32
Name ReviewWait: 'SETTINGS'!$B$33

Sheet START HERE
B1: CLEANING BUSINESS AI GROWTH OS
B2: Run your cleaning business from lead to payment in one connected system.
B3: DEMO FILE — every name, address and number is fictional sample data. Explore it, then use the CLEAN file for your business.
B5: SET UP IN 5 STEPS (about 30 minutes) | E5: COLOR LEGEND
B6: 1. SETTINGS | C6: Enter your business details. Replace the example labor, supply, vehicle and fee assumptions with your own. Leave the as-of date BLANK. | E6: Type here
B7: 2. STAFF & TASKS | C7: Add each worker's name and pay rate (the owner too, if you clean). | E7: Key setting / input
B8: 3. PRICING | C8: Adjust billing rates, time assumptions and add-ons until the rate card matches how you want to price. Test a few quotes. | E8: Automatic — don't type
B9: 4. CUSTOMERS & PROPERTIES | C9: Add current customers and their properties (square feet, bedrooms and bathrooms power automatic time estimates). | E9: Column header you fill
B10: 5. RECURRING & JOBS | C10: Add recurring plans, then your upcoming jobs. From then on: log payments in REVENUE and check the DASHBOARD daily. | E10: Automatic column header ⚙
E11: Needs attention
B12: DAILY FLOW: Lead → Quote → Book → Schedule → Clean → Inspect → Get paid → Review → Referral → Repeat | E12: Below target
E13: Good / done
B14: GET STARTED
B15: START HERE → | C15: This page: setup steps, map and color legend.
B16: DASHBOARD → | C16: Executive dashboard: money, pipeline, operations, reputation and today's action list. | E16: GOLDEN RULES
B17: SETTINGS → | C17: Business details, cost assumptions, targets, dates and all dropdown lists. | E17: • Never type in gray cells or ⚙ columns.
E18: • Keep customer names, property labels and staff names unique.
B19: WIN THE CUSTOMER | E19: • Use dropdowns — they keep the links working.
B20: LEADS → | C20: Lead CRM and sales pipeline: 8 stages, automatic follow-up status and outcome. | E20: • Filter freely; sort a sheet only by selecting the whole table.
B21: QUOTE BUILDER → | C21: Price one job: price, labor cost, direct costs, gross profit, margin and break-even. | E21: • Add rows by typing in the next empty row (1,500 job rows included).
B22: PRICING → | C22: Your pricing assumptions by cleaning type, condition, frequency and add-ons + rate card. | E22: • Back up weekly (File → Save a copy).
B23: CUSTOMERS → | C23: Customer list with lifetime revenue, balance due and a suggested next action. | E23: • Numbers are estimates from your assumptions — not tax, legal or accounting advice.
B24: PROPERTIES → | C24: Property details (size, rooms, access, pets) that feed automatic time estimates.
E25: INCLUDED WITH THIS SYSTEM
B26: DO THE WORK | E26: ✓ Quick Start Guide (PDF)
B27: JOBS → | C27: Every job: schedule, worker, hours, price, payment status and estimated profit. | E27: ✓ Full User Guide (PDF)
B28: RECURRING → | C28: Recurring plans: next visit due, booking status and recurring revenue. | E28: ✓ AI Workflow Library — 18 workflows (PDF)
B29: SCHEDULE → | C29: Weekly calendar built from JOBS + recurring visits that need booking. | E29: ✓ Client Forms — 14 editable templates
B30: STAFF & TASKS → | C30: Team roster with pay rates and monthly output, plus a task assignment list. | E30: ✓ Marketing Kit — print + social templates
B31: SUPPLIES → | C31: Supply inventory with reorder alerts.
B32: QUALITY CONTROL → | C32: Inspection log with pass/fail scores, rework tracking and an issue log.
B33: QC CHECKLISTS → | C33: Six printable checklists: standard, deep, move, Airbnb, commercial, final inspection.
B35: GET PAID & KNOW YOUR NUMBERS
B36: REVENUE → | C36: Payments received, linked to jobs, with processing-fee estimates.
B37: EXPENSES → | C37: Business expenses with overhead flag.
B38: MILEAGE → | C38: Trip log that feeds vehicle cost into each job.
B39: PROFITABILITY → | C39: Profit by service, worker and customer type, for any period.
B40: MONTHLY → | C40: Twelve-month performance: sales, operations, money and growth.
B42: GROW
B43: FOLLOW-UPS → | C43: Automatic list of leads to chase and unpaid jobs, plus your follow-up log.
...

Sheet DASHBOARD
B1: ="EXECUTIVE DASHBOARD · "&UPPER(BizName)
B2: ="Reporting month: "&TEXT(ReportMonth,"mmmm yyyy")&" · As of "&TEXT(AsOf,"mmm d, yyyy")&" · Change dates in SETTINGS"
B3: ← Start Here | D3: Settings →
B4: MONEY — REPORTING MONTH
B5: REVENUE | D5: JOB GROSS PROFIT | F5: GROSS MARGIN | H5: EST. OPERATING PROFIT | J5: PAYMENTS COLLECTED | L5: UNPAID BALANCES (ALL)
B6: =INDEX(MONTHLY!$B$19:$M$19,MONTH(ReportMonth)) | D6: =INDEX(MONTHLY!$B$24:$M$24,MONTH(ReportMonth)) | F6: =INDEX(MONTHLY!$B$25:$M$25,MONTH(ReportMonth)) | H6: =INDEX(MONTHLY!$B$27:$M$27,MONTH(ReportMonth)) | J6: =INDEX(MONTHLY!$B$31:$M$31,MONTH(ReportMonth)) | L6: =SUM('JOBS'!$U$5:$U$1504)
B7: =IFERROR(IF(OR(IF(MONTH(ReportMonth)=1,"",INDEX(MONTHLY!$B$19:$M$19,MONTH(ReportMonth)-1))="",N(IF(MONTH(ReportMonth)=1,"",INDEX(MONTHLY!$B$19:$M$19,MONTH(ReportMonth)-1)))=0),"No prior-month comparison",TEXT(INDEX(MONTHLY!$B$19:$M$19,MONTH(ReportMonth))/IF(MONTH(ReportMonth)=1,"",INDEX(MONTHLY!$B$19:$M$19,MONTH(ReportMonth)-1))-1,"+0%;-0%;0%")&" vs last month"),"No prior-month comparison") | D7: =IFERROR(IF(OR(IF(MONTH(ReportMonth)=1,"",INDEX(MONTHLY!$B$24:$M$24,MONTH(ReportMonth)-1))="",N(IF(MONTH(ReportMonth)=1,"",INDEX(MONTHLY!$B$24:$M$24,MONTH(ReportMonth)-1)))=0),"No prior-month comparison",TEXT(INDEX(MONTHLY!$B$24:$M$24,MONTH(ReportMonth))/IF(MONTH(ReportMonth)=1,"",INDEX(MONTHLY!$B$24:$M$24,MONTH(ReportMonth)-1))-1,"+0%;-0%;0%")&" vs last month"),"No prior-month comparison") | F7: ="Target: "&TEXT(TargetMargin,"0%") | H7: ="After overhead expenses" | J7: ="Incl. tax, by payment date" | L7: =COUNTIF('JOBS'!$V$5:$V$1504,"Unpaid")+COUNTIF('JOBS'!$V$5:$V$1504,"Partial")&" jobs with a balance"
B9: SALES PIPELINE
B10: NEW LEADS | D10: QUOTES GIVEN | F10: LEADS BOOKED | H10: CONVERSION RATE | J10: AVERAGE QUOTE | L10: FOLLOW-UPS DUE NOW
B11: =INDEX(MONTHLY!$B$6:$M$6,MONTH(ReportMonth)) | D11: =INDEX(MONTHLY!$B$7:$M$7,MONTH(ReportMonth)) | F11: =INDEX(MONTHLY!$B$8:$M$8,MONTH(ReportMonth)) | H11: =INDEX(MONTHLY!$B$9:$M$9,MONTH(ReportMonth)) | J11: =INDEX(MONTHLY!$B$10:$M$10,MONTH(ReportMonth)) | L11: =COUNTIF('LEADS'!$P$5:$P$504,"Overdue")+COUNTIF('LEADS'!$P$5:$P$504,"Due today")+COUNTIFS('FOLLOW-UPS'!$G$25:$G$324,"Open",'FOLLOW-UPS'!$A$25:$A$324,"<="&AsOf)
B12: =IFERROR(IF(OR(IF(MONTH(ReportMonth)=1,"",INDEX(MONTHLY!$B$6:$M$6,MONTH(ReportMonth)-1))="",N(IF(MONTH(ReportMonth)=1,"",INDEX(MONTHLY!$B$6:$M$6,MONTH(ReportMonth)-1)))=0),"No prior-month comparison",TEXT(INDEX(MONTHLY!$B$6:$M$6,MONTH(ReportMonth))/IF(MONTH(ReportMonth)=1,"",INDEX(MONTHLY!$B$6:$M$6,MONTH(ReportMonth)-1))-1,"+0%;-0%;0%")&" vs last month"),"No prior-month comparison") | D12: ="Leads added this month with a quote" | F12: ="From this month's leads" | H12: ="Booked ÷ new leads" | J12: ="This month's quotes" | L12: ="Overdue + due today"
B14: OPERATIONS
B15: JOBS COMPLETED | D15: AVERAGE JOB VALUE | F15: REVENUE / LABOR HOUR | H15: JOBS NEXT 7 DAYS | J15: ACTIVE RECURRING PLANS | L15: RECURRING MONTHLY VALUE
B16: =INDEX(MONTHLY!$B$12:$M$12,MONTH(ReportMonth)) | D16: =INDEX(MONTHLY!$B$29:$M$29,MONTH(ReportMonth)) | F16: =INDEX(MONTHLY!$B$30:$M$30,MONTH(ReportMonth)) | H16: =COUNTIFS('JOBS'!$B$5:$B$1504,">="&AsOf,'JOBS'!$B$5:$B$1504,"<="&AsOf+7,'JOBS'!$O$5:$O$1504,"Scheduled") | J16: =COUNTIF('RECURRING'!$J$5:$J$154,"Active") | L16: =SUM('RECURRING'!$R$5:$R$154)
B17: =IFERROR(IF(OR(IF(MONTH(ReportMonth)=1,"",INDEX(MONTHLY!$B$12:$M$12,MONTH(ReportMonth)-1))="",N(IF(MONTH(ReportMonth)=1,"",INDEX(MONTHLY!$B$12:$M$12,MONTH(ReportMonth)-1)))=0),"No prior-month comparison",TEXT(INDEX(MONTHLY!$B$12:$M$12,MONTH(ReportMonth))/IF(MONTH(ReportMonth)=1,"",INDEX(MONTHLY!$B$12:$M$12,MONTH(ReportMonth)-1))-1,"+0%;-0%;0%")&" vs last month"),"No prior-month comparison") | D17: ="Revenue ÷ jobs" | F17: ="All workers combined" | H17: ="Scheduled in JOBS" | J17: =SUMPRODUCT(('CUSTOMERS'!$P$5:$P$404="Yes")*1)&" recurring clients" | L17: ="Active plans, per month"
B19: REPUTATION & QUALITY
B20: REVIEWS RECEIVED | D20: AVERAGE RATING | F20: REFERRALS | H20: QC PASS RATE | J20: OPEN ISSUES | L20: CUSTOMERS TO REACTIVATE
B21: =INDEX(MONTHLY!$B$34:$M$34,MONTH(ReportMonth)) | D21: =IFERROR(AVERAGEIFS('REVIEWS'!$G$5:$G$504,'REVIEWS'!$E$5:$E$504,"Received"),"") | F21: =INDEX(MONTHLY!$B$36:$M$36,MONTH(ReportMonth)) | H21: =IFERROR(COUNTIFS('QUALITY CONTROL'!$P$5:$P$304,ReportMonth,'QUALITY CONTROL'!$N$5:$N$304,"Pass")/COUNTIFS('QUALITY CONTROL'!$P$5:$P$304,ReportMonth,'QUALITY CONTROL'!$N$5:$N$304,"?*"),"") | J21: =COUNTIF('QUALITY CONTROL'!$H$312:$H$461,"Open")+COUNTIF('QUALITY CONTROL'!$H$312:$H$461,"In progress") | L21: =COUNTIF('CUSTOMERS'!$R$5:$R$404,"Reactivate")
B22: ="This month" | D22: ="All-time, received reviews" | F22: =COUNTIF('REFERRALS'!$E$5:$E$204,"Booked")&" booked all-time" | H22: ="Inspections this month" | J22: ="From the issue log" | L22: ="No job in "&ReactDays&"+ days"
B24: ACTION CENTER — what needs attention today | I24: PIPELINE BY STAGE (all leads, current stage)
B25: Leads overdue or due for follow-up | F25: =COUNTIF('LEADS'!$P$5:$P$504,"Overdue")+COUNTIF('LEADS'!$P$5:$P$504,"Due today") | G25: Open Follow-Ups → | I25: Stage | K25: Leads | M25: Quote Value
B26: Other follow-ups overdue / due (your log) | F26: =COUNTIFS('FOLLOW-UPS'!$G$25:$G$324,"Open",'FOLLOW-UPS'!$A$25:$A$324,"<="&AsOf) | G26: Open Follow-Ups → | I26: New Lead | K26: =COUNTIF('LEADS'!$J$5:$J$504,I26) | M26: =SUMIF('LEADS'!$J$5:$J$504,I26,'LEADS'!$I$5:$I$504)
B27: Completed jobs not fully paid | F27: =COUNTIF('JOBS'!$V$5:$V$1504,"Unpaid")+COUNTIF('JOBS'!$V$5:$V$1504,"Partial") | G27: Open Follow-Ups → | I27: Contacted | K27: =COUNTIF('LEADS'!$J$5:$J$504,I27) | M27: =SUMIF('LEADS'!$J$5:$J$504,I27,'LEADS'!$I$5:$I$504)
B28: Recurring visits that need booking | F28: =SUM('RECURRING'!$T$5:$T$154) | G28: Open Schedule → | I28: Quote Requested | K28: =COUNTIF('LEADS'!$J$5:$J$504,I28) | M28: =SUMIF('LEADS'!$J$5:$J$504,I28,'LEADS'!$I$5:$I$504)
B29: Booked leads missing from CUSTOMERS | F29: =COUNTIF('LEADS'!$R$5:$R$504,"Add to CUSTOMERS") | G29: Open Leads → | I29: Quote Sent | K29: =COUNTIF('LEADS'!$J$5:$J$504,I29) | M29: =SUMIF('LEADS'!$J$5:$J$504,I29,'LEADS'!$I$5:$I$504)
B30: Review requests needing a reminder or reply | F30: =COUNTIF('REVIEWS'!$K$5:$K$504,"Send reminder")+COUNTIF('REVIEWS'!$K$5:$K$504,"Reply to review") | G30: Open Reviews → | I30: Follow-Up | K30: =COUNTIF('LEADS'!$J$5:$J$504,I30) | M30: =SUMIF('LEADS'!$J$5:$J$504,I30,'LEADS'!$I$5:$I$504)
B31: Referral rewards owed | F31: =COUNTIF('REFERRALS'!$G$5:$G$204,"Owed") | G31: Open Referrals → | I31: Booked | K31: =COUNTIF('LEADS'!$J$5:$J$504,I31) | M31: =SUMIF('LEADS'!$J$5:$J$504,I31,'LEADS'!$I$5:$I$504)
B32: Rework jobs still open | F32: =COUNTIF('QUALITY CONTROL'!$O$5:$O$304,"Rework open") | G32: Open Quality Control → | I32: Recurring Client | K32: =COUNTIF('LEADS'!$J$5:$J$504,I32) | M32: =SUMIF('LEADS'!$J$5:$J$504,I32,'LEADS'!$I$5:$I$504)
B33: Supplies at or below reorder level | F33: =COUNTIF('SUPPLIES'!$K$5:$K$104,"Reorder") | G33: Open Supplies → | I33: Lost/Declined | K33: =COUNTIF('LEADS'!$J$5:$J$504,I33) | M33: =SUMIF('LEADS'!$J$5:$J$504,I33,'LEADS'!$I$5:$I$504)
B34: Overdue staff tasks | F34: =COUNTIF('STAFF & TASKS'!$H$31:$H$230,"Overdue") | G34: Open Staff & Tasks →
B37: TRENDS
B54: All figures come from your logs and your assumptions. They are management estimates, not accounting, tax or legal advice.

Sheet LEADS
A1: LEAD CRM & SALES PIPELINE
A2: One row per lead. Move the Stage as the lead progresses. Follow-up status, outcome and 'add to customers' reminders are automatic.
A3: ← Start Here | B3: Dashboard →
A4: Lead ID | B4: Date Added | C4: Name | D4: Phone | E4: Email | F4: Lead Source | G4: Requested Service | H4: Area / Property Notes | I4: Quote Value ($) | J4: Stage | K4: Last Contact | L4: Next Follow-Up | M4: Lost Reason | N4: Notes | O4: Booking Outcome ⚙ | P4: Follow-Up Status ⚙ | Q4: Days Since Added ⚙ | R4: Customer Record ⚙ | S4: Open? (1/0) ⚙ | T4: Month ⚙ | U4: Follow-Up Order ⚙
A5: L-0001 | B5: 46024 | C5: Dana Collins | D5: 555-0109 | E5: dana.collins@example.com | F5: Google Business Profile | G5: Deep Clean | H5: Lakeview (fictional) | I5: 450 | J5: Recurring Client | K5: 46025 | O5: =IF(C5="","",IF(OR(J5="Booked",J5="Recurring Client"),"Booked",IF(J5="Lost/Declined","Lost","Open"))) | P5: =IF(C5="","",IF(S5=0,"—",IF(L5="","Set date",IF(L5<AsOf,"Overdue",IF(L5=AsOf,"Due today",IF(L5<=AsOf+SoonDays,"Due soon","Scheduled")))))) | Q5: =IF(C5="","",IF(B5="","",AsOf-B5)) | R5: =IF(C5="","",IF(O5<>"Booked","",IF(COUNTIF('CUSTOMERS'!$B$5:$B$404,C5)>0,"✓ In CUSTOMERS","Add to CUSTOMERS"))) | S5: =IF(C5="","",IF(OR(J5="Booked",J5="Recurring Client",J5="Lost/Declined"),0,1)) | T5: =IF(B5="","",DATE(YEAR(B5),MONTH(B5),1)) | U5: =IF(OR(S5<>1,L5=""),"",COUNTIFS('LEADS'!$S$5:$S$504,1,'LEADS'!$L$5:$L$504,"<"&L5)+COUNTIFS($S$5:S5,1,$L$5:L5,L5))
A6: L-0002 | B6: 46030 | C6: Lane Northcott | D6: 555-0113 | E6: lane.northcott@example.com | F6: Google Business Profile | G6: Deep Clean | H6: Lakeview (fictional) | I6: 345 | J6: Recurring Client | K6: 46031 | O6: =IF(C6="","",IF(OR(J6="Booked",J6="Recurring Client"),"Booked",IF(J6="Lost/Declined","Lost","Open"))) | P6: =IF(C6="","",IF(S6=0,"—",IF(L6="","Set date",IF(L6<AsOf,"Overdue",IF(L6=AsOf,"Due today",IF(L6<=AsOf+SoonDays,"Due soon","Scheduled")))))) | Q6: =IF(C6="","",IF(B6="","",AsOf-B6)) | R6: =IF(C6="","",IF(O6<>"Booked","",IF(COUNTIF('CUSTOMERS'!$B$5:$B$404,C6)>0,"✓ In CUSTOMERS","Add to CUSTOMERS"))) | S6: =IF(C6="","",IF(OR(J6="Booked",J6="Recurring Client",J6="Lost/Declined"),0,1)) | T6: =IF(B6="","",DATE(YEAR(B6),MONTH(B6),1)) | U6: =IF(OR(S6<>1,L6=""),"",COUNTIFS('LEADS'!$S$5:$S$504,1,'LEADS'!$L$5:$L$504,"<"&L6)+COUNTIFS($S$5:S6,1,$L$5:L6,L6))
A7: L-0003 | B7: 46032 | C7: Elliot Collins | D7: 555-0150 | E7: elliot.collins@example.com | F7: Facebook | G7: Move-In/Move-Out | H7: Riverbend (fictional) | I7: 340 | J7: Lost/Declined | K7: 46034 | M7: Price | O7: =IF(C7="","",IF(OR(J7="Booked",J7="Recurring Client"),"Booked",IF(J7="Lost/Declined","Lost","Open"))) | P7: =IF(C7="","",IF(S7=0,"—",IF(L7="","Set date",IF(L7<AsOf,"Overdue",IF(L7=AsOf,"Due today",IF(L7<=AsOf+SoonDays,"Due soon","Scheduled")))))) | Q7: =IF(C7="","",IF(B7="","",AsOf-B7)) | R7: =IF(C7="","",IF(O7<>"Booked","",IF(COUNTIF('CUSTOMERS'!$B$5:$B$404,C7)>0,"✓ In CUSTOMERS","Add to CUSTOMERS"))) | S7: =IF(C7="","",IF(OR(J7="Booked",J7="Recurring Client",J7="Lost/Declined"),0,1)) | T7: =IF(B7="","",DATE(YEAR(B7),MONTH(B7),1)) | U7: =IF(OR(S7<>1,L7=""),"",COUNTIFS('LEADS'!$S$5:$S$504,1,'LEADS'!$L$5:$L$504,"<"&L7)+COUNTIFS($S$5:S7,1,$L$5:L7,L7))
A8: L-0004 | B8: 46033 | C8: Micah Quigley | D8: 555-0141 | E8: micah.quigley@example.com | F8: Flyer / Door Hanger | G8: Standard Clean | H8: Sampletown | I8: 160 | J8: Lost/Declined | K8: 46040 | M8: Price | O8: =IF(C8="","",IF(OR(J8="Booked",J8="Recurring Client"),"Booked",IF(J8="Lost/Declined","Lost","Open"))) | P8: =IF(C8="","",IF(S8=0,"—",IF(L8="","Set date",IF(L8<AsOf,"Overdue",IF(L8=AsOf,"Due today",IF(L8<=AsOf+SoonDays,"Due soon","Scheduled")))))) | Q8: =IF(C8="","",IF(B8="","",AsOf-B8)) | R8: =IF(C8="","",IF(O8<>"Booked","",IF(COUNTIF('CUSTOMERS'!$B$5:$B$404,C8)>0,"✓ In CUSTOMERS","Add to CUSTOMERS"))) | S8: =IF(C8="","",IF(OR(J8="Booked",J8="Recurring Client",J8="Lost/Declined"),0,1)) | T8: =IF(B8="","",DATE(YEAR(B8),MONTH(B8),1)) | U8: =IF(OR(S8<>1,L8=""),"",COUNTIFS('LEADS'!$S$5:$S$504,1,'LEADS'!$L$5:$L$504,"<"&L8)+COUNTIFS($S$5:S8,1,$L$5:L8,L8))
A9: L-0005 | B9: 46035 | C9: Dana Oakes | D9: 555-0129 | E9: dana.oakes@example.com | F9: Facebook | G9: Airbnb Turnover | H9: North Sampletown | I9: 135 | J9: Booked | K9: 46036 | O9: =IF(C9="","",IF(OR(J9="Booked",J9="Recurring Client"),"Booked",IF(J9="Lost/Declined","Lost","Open"))) | P9: =IF(C9="","",IF(S9=0,"—",IF(L9="","Set date",IF(L9<AsOf,"Overdue",IF(L9=AsOf,"Due today",IF(L9<=AsOf+SoonDays,"Due soon","Scheduled")))))) | Q9: =IF(C9="","",IF(B9="","",AsOf-B9)) | R9: =IF(C9="","",IF(O9<>"Booked","",IF(COUNTIF('CUSTOMERS'!$B$5:$B$404,C9)>0,"✓ In CUSTOMERS","Add to CUSTOMERS"))) | S9: =IF(C9="","",IF(OR(J9="Booked",J9="Recurring Client",J9="Lost/Declined"),0,1)) | T9: =IF(B9="","",DATE(YEAR(B9),MONTH(B9),1)) | U9: =IF(OR(S9<>1,L9=""),"",COUNTIFS('LEADS'!$S$5:$S$504,1,'LEADS'!$L$5:$L$504,"<"&L9)+COUNTIFS($S$5:S9,1,$L$5:L9,L9))
A10: L-0006 | B10: 46036 | C10: Taylor Quigley | D10: 555-0112 | E10: taylor.quigley@example.com | F10: Flyer / Door Hanger | G10: Deep Clean | H10: Sampletown | I10: 330 | J10: Recurring Client | K10: 46037 | O10: =IF(C10="","",IF(OR(J10="Booked",J10="Recurring Client"),"Booked",IF(J10="Lost/Declined","Lost","Open"))) | P10: =IF(C10="","",IF(S10=0,"—",IF(L10="","Set date",IF(L10<AsOf,"Overdue",IF(L10=AsOf,"Due today",IF(L10<=AsOf+SoonDays,"Due soon","Scheduled")))))) | Q10: =IF(C10="","",IF(B10="","",AsOf-B10)) | R10: =IF(C10="","",IF(O10<>"Booked","",IF(COUNTIF('CUSTOMERS'!$B$5:$B$404,C10)>0,"✓ In CUSTOMERS","Add to CUSTOMERS"))) | S10: =IF(C10="","",IF(OR(J10="Booked",J10="Recurring Client",J10="Lost/Declined"),0,1)) | T10: =IF(B10="","",DATE(YEAR(B10),MONTH(B10),1)) | U10: =IF(OR(S10<>1,L10=""),"",COUNTIFS('LEADS'!$S$5:$S$504,1,'LEADS'!$L$5:$L$504,"<"&L10)+COUNTIFS($S$5:S10,1,$L$5:L10,L10))
A11: L-0007 | B11: 46036 | C11: Emerson Holloway | D11: 555-0131 | E11: emerson.holloway@example.com | F11: Google Business Profile | G11: Airbnb Turnover | H11: North Sampletown | I11: 150 | J11: Booked | K11: 46037 | O11: =IF(C11="","",IF(OR(J11="Booked",J11="Recurring Client"),"Booked",IF(J11="Lost/Declined","Lost","Open"))) | P11: =IF(C11="","",IF(S11=0,"—",IF(L11="","Set date",IF(L11<AsOf,"Overdue",IF(L11=AsOf,"Due today",IF(L11<=AsOf+SoonDays,"Due soon","Scheduled")))))) | Q11: =IF(C11="","",IF(B11="","",AsOf-B11)) | R11: =IF(C11="","",IF(O11<>"Booked","",IF(COUNTIF('CUSTOMERS'!$B$5:$B$404,C11)>0,"✓ In CUSTOMERS","Add to CUSTOMERS"))) | S11: =IF(C11="","",IF(OR(J11="Booked",J11="Recurring Client",J11="Lost/Declined"),0,1)) | T11: =IF(B11="","",DATE(YEAR(B11),MONTH(B11),1)) | U11: =IF(OR(S11<>1,L11=""),"",COUNTIFS('LEADS'!$S$5:$S$504,1,'LEADS'!$L$5:$L$504,"<"&L11)+COUNTIFS($S$5:S11,1,$L$5:L11,L11))
A12: L-0008 | B12: 46038 | C12: Blake Oakes | D12: 555-0130 | E12: blake.oakes@example.com | F12: Google Search | G12: Airbnb Turnover | H12: North Sampletown | I12: 135 | J12: Booked | K12: 46039 | O12: =IF(C12="","",IF(OR(J12="Booked",J12="Recurring Client"),"Booked",IF(J12="Lost/Declined","Lost","Open"))) | P12: =IF(C12="","",IF(S12=0,"—",IF(L12="","Set date",IF(L12<AsOf,"Overdue",IF(L12=AsOf,"Due today",IF(L12<=AsOf+SoonDays,"Due soon","Scheduled")))))) | Q12: =IF(C12="","",IF(B12="","",AsOf-B12)) | R12: =IF(C12="","",IF(O12<>"Booked","",IF(COUNTIF('CUSTOMERS'!$B$5:$B$404,C12)>0,"✓ In CUSTOMERS","Add to CUSTOMERS"))) | S12: =IF(C12="","",IF(OR(J12="Booked",J12="Recurring Client",J12="Lost/Declined"),0,1)) | T12: =IF(B12="","",DATE(YEAR(B12),MONTH(B12),1)) | U12: =IF(OR(S12<>1,L12=""),"",COUNTIFS('LEADS'!$S$5:$S$504,1,'LEADS'!$L$5:$L$504,"<"&L12)+COUNTIFS($S$5:S12,1,$L$5:L12,L12))
A13: L-0009 | B13: 46042 | C13: Lane Ivers | D13: 555-0104 | E13: lane.ivers@example.com | F13: Website Form | G13: Deep Clean | H13: Sampletown | I13: 450 | J13: Recurring Client | K13: 46043 | O13: =IF(C13="","",IF(OR(J13="Booked",J13="Recurring Client"),"Booked",IF(J13="Lost/Declined","Lost","Open"))) | P13: =IF(C13="","",IF(S13=0,"—",IF(L13="","Set date",IF(L13<AsOf,"Overdue",IF(L13=AsOf,"Due today",IF(L13<=AsOf+SoonDays,"Due soon","Scheduled")))))) | Q13: =IF(C13="","",IF(B13="","",AsOf-B13)) | R13: =IF(C13="","",IF(O13<>"Booked","",IF(COUNTIF('CUSTOMERS'!$B$5:$B$404,C13)>0,"✓ In CUSTOMERS","Add to CUSTOMERS"))) | S13: =IF(C13="","",IF(OR(J13="Booked",J13="Recurring Client",J13="Lost/Declined"),0,1)) | T13: =IF(B13="","",DATE(YEAR(B13),MONTH(B13),1)) | U13: =IF(OR(S13<>1,L13=""),"",COUNTIFS('LEADS'!$S$5:$S$504,1,'LEADS'!$L$5:$L$504,"<"&L13)+COUNTIFS($S$5:S13,1,$L$5:L13,L13))
A14: L-0010 | B14: 46045 | C14: Dana Hartwell | D14: 555-0158 | E14: dana.hartwell@example.com | F14: Google Search | G14: Move-In/Move-Out | H14: Lakeview (fictional) | I14: 395 | J14: Lost/Declined | K14: 46053 | M14: Timing / availability | O14: =IF(C14="","",IF(OR(J14="Booked",J14="Recurring Client"),"Booked",IF(J14="Lost/Declined","Lost","Open"))) | P14: =IF(C14="","",IF(S14=0,"—",IF(L14="","Set date",IF(L14<AsOf,"Overdue",IF(L14=AsOf,"Due today",IF(L14<=AsOf+SoonDays,"Due soon","Scheduled")))))) | Q14: =IF(C14="","",IF(B14="","",AsOf-B14)) | R14: =IF(C14="","",IF(O14<>"Booked","",IF(COUNTIF('CUSTOMERS'!$B$5:$B$404,C14)>0,"✓ In CUSTOMERS","Add to CUSTOMERS"))) | S14: =IF(C14="","",IF(OR(J14="Booked",J14="Recurring Client",J14="Lost/Declined"),0,1)) | T14: =IF(B14="","",DATE(YEAR(B14),MONTH(B14),1)) | U14: =IF(OR(S14<>1,L14=""),"",COUNTIFS('LEADS'!$S$5:$S$504,1,'LEADS'!$L$5:$L$504,"<"&L14)+COUNTIFS($S$5:S14,1,$L$5:L14,L14))
A15: L-0011 | B15: 46046 | C15: Parker Lockhart | D15: 555-0132 | E15: parker.lockhart@example.com | F15: Google Search | G15: Airbnb Turnover | H15: Sampletown | I15: 150 | J15: Booked | K15: 46047 | O15: =IF(C15="","",IF(OR(J15="Booked",J15="Recurring Client"),"Booked",IF(J15="Lost/Declined","Lost","Open"))) | P15: =IF(C15="","",IF(S15=0,"—",IF(L15="","Set date",IF(L15<AsOf,"Overdue",IF(L15=AsOf,"Due today",IF(L15<=AsOf+SoonDays,"Due soon","Scheduled")))))) | Q15: =IF(C15="","",IF(B15="","",AsOf-B15)) | R15: =IF(C15="","",IF(O15<>"Booked","",IF(COUNTIF('CUSTOMERS'!$B$5:$B$404,C15)>0,"✓ In CUSTOMERS","Add to CUSTOMERS"))) | S15: =IF(C15="","",IF(OR(J15="Booked",J15="Recurring Client",J15="Lost/Declined"),0,1)) | T15: =IF(B15="","",DATE(YEAR(B15),MONTH(B15),1)) | U15: =IF(OR(S15<>1,L15=""),"",COUNTIFS('LEADS'!$S$5:$S$504,1,'LEADS'!$L$5:$L$504,"<"&L15)+COUNTIFS($S$5:S15,1,$L$5:L15,L15))
A16: L-0012 | B16: 46049 | C16: Brightside Dental Studio (sample) | D16: 555-0126 | E16: brightside.dental.studio.(sample)@example.com | F16: Referral | G16: Commercial Clean | H16: North Sampletown | I16: 100 | J16: Recurring Client | K16: 46050 | O16: =IF(C16="","",IF(OR(J16="Booked",J16="Recurring Client"),"Booked",IF(J16="Lost/Declined","Lost","Open"))) | P16: =IF(C16="","",IF(S16=0,"—",IF(L16="","Set date",IF(L16<AsOf,"Overdue",IF(L16=AsOf,"Due today",IF(L16<=AsOf+SoonDays,"Due soon","Scheduled")))))) | Q16: =IF(C16="","",IF(B16="","",AsOf-B16)) | R16: =IF(C16="","",IF(O16<>"Booked","",IF(COUNTIF('CUSTOMERS'!$B$5:$B$404,C16)>0,"✓ In CUSTOMERS","Add to CUSTOMERS"))) | S16: =IF(C16="","",IF(OR(J16="Booked",J16="Recurring Client",J16="Lost/Declined"),0,1)) | T16: =IF(B16="","",DATE(YEAR(B16),MONTH(B16),1)) | U16: =IF(OR(S16<>1,L16=""),"",COUNTIFS('LEADS'!$S$5:$S$504,1,'LEADS'!$L$5:$L$504,"<"&L16)+COUNTIFS($S$5:S16,1,$L$5:L16,L16))
A17: L-0013 | B17: 46050 | C17: Wren Porter | D17: 555-0123 | E17: wren.porter@example.com | F17: Referral | G17: Deep Clean | H17: North Sampletown | I17: 685 | J17: Booked | K17: 46051 | O17: =IF(C17="","",IF(OR(J17="Booked",J17="Recurring Client"),"Booked",IF(J17="Lost/Declined","Lost","Open"))) | P17: =IF(C17="","",IF(S17=0,"—",IF(L17="","Set date",IF(L17<AsOf,"Overdue",IF(L17=AsOf,"Due today",IF(L17<=AsOf+SoonDays,"Due soon","Scheduled")))))) | Q17: =IF(C17="","",IF(B17="","",AsOf-B17)) | R17: =IF(C17="","",IF(O17<>"Booked","",IF(COUNTIF('CUSTOMERS'!$B$5:$B$404,C17)>0,"✓ In CUSTOMERS","Add to CUSTOMERS"))) | S17: =IF(C17="","",IF(OR(J17="Booked",J17="Recurring Client",J17="Lost/Declined"),0,1)) | T17: =IF(B17="","",DATE(YEAR(B17),MONTH(B17),1)) | U17: =IF(OR(S17<>1,L17=""),"",COUNTIFS('LEADS'!$S$5:$S$504,1,'LEADS'!$L$5:$L$504,"<"&L17)+COUNTIFS($S$5:S17,1,$L$5:L17,L17))
A18: L-0014 | B18: 46052 | C18: Dana Delgado | D18: 555-0163 | E18: dana.delgado@example.com | F18: Google Business Profile | G18: Airbnb Turnover | H18: Riverbend (fictional) | J18: Lost/Declined | K18: 46057 | M18: No response | O18: =IF(C18="","",IF(OR(J18="Booked",J18="Recurring Client"),"Booked",IF(J18="Lost/Declined","Lost","Open"))) | P18: =IF(C18="","",IF(S18=0,"—",IF(L18="","Set date",IF(L18<AsOf,"Overdue",IF(L18=AsOf,"Due today",IF(L18<=AsOf+SoonDays,"Due soon","Scheduled")))))) | Q18: =IF(C18="","",IF(B18="","",AsOf-B18)) | R18: =IF(C18="","",IF(O18<>"Booked","",IF(COUNTIF('CUSTOMERS'!$B$5:$B$404,C18)>0,"✓ In CUSTOMERS","Add to CUSTOMERS"))) | S18: =IF(C18="","",IF(OR(J18="Booked",J18="Recurring Client",J18="Lost/Declined"),0,1)) | T18: =IF(B18="","",DATE(YEAR(B18),MONTH(B18),1)) | U18: =IF(OR(S18<>1,L18=""),"",COUNTIFS('LEADS'!$S$5:$S$504,1,'LEADS'!$L$5:$L$504,"<"&L18)+COUNTIFS($S$5:S18,1,$L$5:L18,L18))
A19: L-0015 | B19: 46055 | C19: Peyton Thornbury | D19: 555-0157 | E19: peyton.thornbury@example.com | F19: Referral | G19: Standard Clean | H19: Lakeview (fictional) | I19: 285 | J19: Lost/Declined | K19: 46060 | M19: No response | O19: =IF(C19="","",IF(OR(J19="Booked",J19="Recurring Client"),"Booked",IF(J19="Lost/Declined","Lost","Open"))) | P19: =IF(C19="","",IF(S19=0,"—",IF(L19="","Set date",IF(L19<AsOf,"Overdue",IF(L19=AsOf,"Due today",IF(L19<=AsOf+SoonDays,"Due soon","Scheduled")))))) | Q19: =IF(C19="","",IF(B19="","",AsOf-B19)) | R19: =IF(C19="","",IF(O19<>"Booked","",IF(COUNTIF('CUSTOMERS'!$B$5:$B$404,C19)>0,"✓ In CUSTOMERS","Add to CUSTOMERS"))) | S19: =IF(C19="","",IF(OR(J19="Booked",J19="Recurring Client",J19="Lost/Declined"),0,1)) | T19: =IF(B19="","",DATE(YEAR(B19),MONTH(B19),1)) | U19: =IF(OR(S19<>1,L19=""),"",COUNTIFS('LEADS'!$S$5:$S$504,1,'LEADS'!$L$5:$L$504,"<"&L19)+COUNTIFS($S$5:S19,1,$L$5:L19,L19))
A20: L-0016 | B20: 46062 | C20: Drew Underhill | D20: 555-0145 | E20: drew.underhill@example.com | F20: Flyer / Door Hanger | G20: Move-In/Move-Out | H20: Riverbend (fictional) | I20: 395 | J20: Lost/Declined | K20: 46068 | M20: Outside service area | O20: =IF(C20="","",IF(OR(J20="Booked",J20="Recurring Client"),"Booked",IF(J20="Lost/Declined","Lost","Open"))) | P20: =IF(C20="","",IF(S20=0,"—",IF(L20="","Set date",IF(L20<AsOf,"Overdue",IF(L20=AsOf,"Due today",IF(L20<=AsOf+SoonDays,"Due soon","Scheduled")))))) | Q20: =IF(C20="","",IF(B20="","",AsOf-B20)) | R20: =IF(C20="","",IF(O20<>"Booked","",IF(COUNTIF('CUSTOMERS'!$B$5:$B$404,C20)>0,"✓ In CUSTOMERS","Add to CUSTOMERS"))) | S20: =IF(C20="","",IF(OR(J20="Booked",J20="Recurring Client",J20="Lost/Declined"),0,1)) | T20: =IF(B20="","",DATE(YEAR(B20),MONTH(B20),1)) | U20: =IF(OR(S20<>1,L20=""),"",COUNTIFS('LEADS'!$S$5:$S$504,1,'LEADS'!$L$5:$L$504,"<"&L20)+COUNTIFS($S$5:S20,1,$L$5:L20,L20))
A21: L-0017 | B21: 46067 | C21: Arden Northcott | D21: 555-0155 | E21: arden.northcott@example.com | F21: Referral | G21: Move-In/Move-Out | H21: Lakeview (fictional) | J21: Lost/Declined | K21: 46069 | M21: Price | O21: =IF(C21="","",IF(OR(J21="Booked",J21="Recurring Client"),"Booked",IF(J21="Lost/Declined","Lost","Open"))) | P21: =IF(C21="","",IF(S21=0,"—",IF(L21="","Set date",IF(L21<AsOf,"Overdue",IF(L21=AsOf,"Due today",IF(L21<=AsOf+SoonDays,"Due soon","Scheduled")))))) | Q21: =IF(C21="","",IF(B21="","",AsOf-B21)) | R21: =IF(C21="","",IF(O21<>"Booked","",IF(COUNTIF('CUSTOMERS'!$B$5:$B$404,C21)>0,"✓ In CUSTOMERS","Add to CUSTOMERS"))) | S21: =IF(C21="","",IF(OR(J21="Booked",J21="Recurring Client",J21="Lost/Declined"),0,1)) | T21: =IF(B21="","",DATE(YEAR(B21),MONTH(B21),1)) | U21: =IF(OR(S21<>1,L21=""),"",COUNTIFS('LEADS'!$S$5:$S$504,1,'LEADS'!$L$5:$L$504,"<"&L21)+COUNTIFS($S$5:S21,1,$L$5:L21,L21))
A22: L-0018 | B22: 46068 | C22: Skyler Winslow | D22: 555-0146 | E22: skyler.winslow@example.com | F22: Facebook | G22: Airbnb Turnover | H22: North Sampletown | I22: 395 | J22: Lost/Declined | K22: 46070 | M22: Timing / availability | O22: =IF(C22="","",IF(OR(J22="Booked",J22="Recurring Client"),"Booked",IF(J22="Lost/Declined","Lost","Open"))) | P22: =IF(C22="","",IF(S22=0,"—",IF(L22="","Set date",IF(L22<AsOf,"Overdue",IF(L22=AsOf,"Due today",IF(L22<=AsOf+SoonDays,"Due soon","Scheduled")))))) | Q22: =IF(C22="","",IF(B22="","",AsOf-B22)) | R22: =IF(C22="","",IF(O22<>"Booked","",IF(COUNTIF('CUSTOMERS'!$B$5:$B$404,C22)>0,"✓ In CUSTOMERS","Add to CUSTOMERS"))) | S22: =IF(C22="","",IF(OR(J22="Booked",J22="Recurring Client",J22="Lost/Declined"),0,1)) | T22: =IF(B22="","",DATE(YEAR(B22),MONTH(B22),1)) | U22: =IF(OR(S22<>1,L22=""),"",COUNTIFS('LEADS'!$S$5:$S$504,1,'LEADS'!$L$5:$L$504,"<"&L22)+COUNTIFS($S$5:S22,1,$L$5:L22,L22))
A23: L-0019 | B23: 46073 | C23: Crescent Property Group (sample) | D23: 555-0133 | E23: crescent.property.group.(sample)@example.com | F23: Google Business Profile | G23: Move-In/Move-Out | H23: North Sampletown | I23: 300 | J23: Booked | K23: 46074 | O23: =IF(C23="","",IF(OR(J23="Booked",J23="Recurring Client"),"Booked",IF(J23="Lost/Declined","Lost","Open"))) | P23: =IF(C23="","",IF(S23=0,"—",IF(L23="","Set date",IF(L23<AsOf,"Overdue",IF(L23=AsOf,"Due today",IF(L23<=AsOf+SoonDays,"Due soon","Scheduled")))))) | Q23: =IF(C23="","",IF(B23="","",AsOf-B23)) | R23: =IF(C23="","",IF(O23<>"Booked","",IF(COUNTIF('CUSTOMERS'!$B$5:$B$404,C23)>0,"✓ In CUSTOMERS","Add to CUSTOMERS"))) | S23: =IF(C23="","",IF(OR(J23="Booked",J23="Recurring Client",J23="Lost/Declined"),0,1)) | T23: =IF(B23="","",DATE(YEAR(B23),MONTH(B23),1)) | U23: =IF(OR(S23<>1,L23=""),"",COUNTIFS('LEADS'!$S$5:$S$504,1,'LEADS'!$L$5:$L$504,"<"&L23)+COUNTIFS($S$5:S23,1,$L$5:L23,L23))
A24: L-0020 | B24: 46075 | C24: Rory Vance | D24: 555-0140 | E24: rory.vance@example.com | F24: Google Business Profile | G24: Airbnb Turnover | H24: Old Mill District | I24: 395 | J24: Lost/Declined | K24: 46078 | M24: Timing / availability | O24: =IF(C24="","",IF(OR(J24="Booked",J24="Recurring Client"),"Booked",IF(J24="Lost/Declined","Lost","Open"))) | P24: =IF(C24="","",IF(S24=0,"—",IF(L24="","Set date",IF(L24<AsOf,"Overdue",IF(L24=AsOf,"Due today",IF(L24<=AsOf+SoonDays,"Due soon","Scheduled")))))) | Q24: =IF(C24="","",IF(B24="","",AsOf-B24)) | R24: =IF(C24="","",IF(O24<>"Booked","",IF(COUNTIF('CUSTOMERS'!$B$5:$B$404,C24)>0,"✓ In CUSTOMERS","Add to CUSTOMERS"))) | S24: =IF(C24="","",IF(OR(J24="Booked",J24="Recurring Client",J24="Lost/Declined"),0,1)) | T24: =IF(B24="","",DATE(YEAR(B24),MONTH(B24),1)) | U24: =IF(OR(S24<>1,L24=""),"",COUNTIFS('LEADS'!$S$5:$S$504,1,'LEADS'!$L$5:$L$504,"<"&L24)+COUNTIFS($S$5:S24,1,$L$5:L24,L24))
A25: L-0021 | B25: 46079 | C25: Peyton Underhill | D25: 555-0114 | E25: peyton.underhill@example.com | F25: Referral | G25: Deep Clean | H25: Sampletown | I25: 300 | J25: Booked | K25: 46080 | O25: =IF(C25="","",IF(OR(J25="Booked",J25="Recurring Client"),"Booked",IF(J25="Lost/Declined","Lost","Open"))) | P25: =IF(C25="","",IF(S25=0,"—",IF(L25="","Set date",IF(L25<AsOf,"Overdue",IF(L25=AsOf,"Due today",IF(L25<=AsOf+SoonDays,"Due soon","Scheduled")))))) | Q25: =IF(C25="","",IF(B25="","",AsOf-B25)) | R25: =IF(C25="","",IF(O25<>"Booked","",IF(COUNTIF('CUSTOMERS'!$B$5:$B$404,C25)>0,"✓ In CUSTOMERS","Add to CUSTOMERS"))) | S25: =IF(C25="","",IF(OR(J25="Booked",J25="Recurring Client",J25="Lost/Declined"),0,1)) | T25: =IF(B25="","",DATE(YEAR(B25),MONTH(B25),1)) | U25: =IF(OR(S25<>1,L25=""),"",COUNTIFS('LEADS'!$S$5:$S$504,1,'LEADS'!$L$5:$L$504,"<"&L25)+COUNTIFS($S$5:S25,1,$L$5:L25,L25))
A26: L-0022 | B26: 46080 | C26: Noel Hayes | D26: 555-0135 | E26: noel.hayes@example.com | F26: Referral | G26: Standard Clean | H26: Sampletown | I26: 160 | J26: Lost/Declined | K26: 46085 | M26: Timing / availability | O26: =IF(C26="","",IF(OR(J26="Booked",J26="Recurring Client"),"Booked",IF(J26="Lost/Declined","Lost","Open"))) | P26: =IF(C26="","",IF(S26=0,"—",IF(L26="","Set date",IF(L26<AsOf,"Overdue",IF(L26=AsOf,"Due today",IF(L26<=AsOf+SoonDays,"Due soon","Scheduled")))))) | Q26: =IF(C26="","",IF(B26="","",AsOf-B26)) | R26: =IF(C26="","",IF(O26<>"Booked","",IF(COUNTIF('CUSTOMERS'!$B$5:$B$404,C26)>0,"✓ In CUSTOMERS","Add to CUSTOMERS"))) | S26: =IF(C26="","",IF(OR(J26="Booked",J26="Recurring Client",J26="Lost/Declined"),0,1)) | T26: =IF(B26="","",DATE(YEAR(B26),MONTH(B26),1)) | U26: =IF(OR(S26<>1,L26=""),"",COUNTIFS('LEADS'!$S$5:$S$504,1,'LEADS'!$L$5:$L$504,"<"&L26)+COUNTIFS($S$5:S26,1,$L$5:L26,L26))
A27: L-0023 | B27: 46086 | C27: Harbor Yoga Loft (sample) | D27: 555-0128 | E27: harbor.yoga.loft.(sample)@example.com | F27: Nextdoor | G27: Commercial Clean | H27: Sampletown | I27: 160 | J27: Booked | K27: 46087 | O27: =IF(C27="","",IF(OR(J27="Booked",J27="Recurring Client"),"Booked",IF(J27="Lost/Declined","Lost","Open"))) | P27: =IF(C27="","",IF(S27=0,"—",IF(L27="","Set date",IF(L27<AsOf,"Overdue",IF(L27=AsOf,"Due today",IF(L27<=AsOf+SoonDays,"Due soon","Scheduled")))))) | Q27: =IF(C27="","",IF(B27="","",AsOf-B27)) | R27: =IF(C27="","",IF(O27<>"Booked","",IF(COUNTIF('CUSTOMERS'!$B$5:$B$404,C27)>0,"✓ In CUSTOMERS","Add to CUSTOMERS"))) | S27: =IF(C27="","",IF(OR(J27="Booked",J27="Recurring Client",J27="Lost/Declined"),0,1)) | T27: =IF(B27="","",DATE(YEAR(B27),MONTH(B27),1)) | U27: =IF(OR(S27<>1,L27=""),"",COUNTIFS('LEADS'!$S$5:$S$504,1,'LEADS'!$L$5:$L$504,"<"&L27)+COUNTIFS($S$5:S27,1,$L$5:L27,L27))
A28: L-0024 | B28: 46086 | C28: Avery Brightwater | D28: 555-0159 | E28: avery.brightwater@example.com | F28: Website Form | G28: Airbnb Turnover | H28: Riverbend (fictional) | I28: 340 | J28: Lost/Declined | K28: 46090 | M28: Outside service area | O28: =IF(C28="","",IF(OR(J28="Booked",J28="Recurring Client"),"Booked",IF(J28="Lost/Declined","Lost","Open"))) | P28: =IF(C28="","",IF(S28=0,"—",IF(L28="","Set date",IF(L28<AsOf,"Overdue",IF(L28=AsOf,"Due today",IF(L28<=AsOf+SoonDays,"Due soon","Scheduled")))))) | Q28: =IF(C28="","",IF(B28="","",AsOf-B28)) | R28: =IF(C28="","",IF(O28<>"Booked","",IF(COUNTIF('CUSTOMERS'!$B$5:$B$404,C28)>0,"✓ In CUSTOMERS","Add to CUSTOMERS"))) | S28: =IF(C28="","",IF(OR(J28="Booked",J28="Recurring Client",J28="Lost/Declined"),0,1)) | T28: =IF(B28="","",DATE(YEAR(B28),MONTH(B28),1)) | U28: =IF(OR(S28<>1,L28=""),"",COUNTIFS('LEADS'!$S$5:$S$504,1,'LEADS'!$L$5:$L$504,"<"&L28)+COUNTIFS($S$5:S28,1,$L$5:L28,L28))
A29: L-0025 | B29: 46089 | C29: Rowan Foxworth | D29: 555-0108 | E29: rowan.foxworth@example.com | F29: Google Search | G29: Deep Clean | H29: North Sampletown | I29: 530 | J29: Recurring Client | K29: 46090 | O29: =IF(C29="","",IF(OR(J29="Booked",J29="Recurring Client"),"Booked",IF(J29="Lost/Declined","Lost","Open"))) | P29: =IF(C29="","",IF(S29=0,"—",IF(L29="","Set date",IF(L29<AsOf,"Overdue",IF(L29=AsOf,"Due today",IF(L29<=AsOf+SoonDays,"Due soon","Scheduled")))))) | Q29: =IF(C29="","",IF(B29="","",AsOf-B29)) | R29: =IF(C29="","",IF(O29<>"Booked","",IF(COUNTIF('CUSTOMERS'!$B$5:$B$404,C29)>0,"✓ In CUSTOMERS","Add to CUSTOMERS"))) | S29: =IF(C29="","",IF(OR(J29="Booked",J29="Recurring Client",J29="Lost/Declined"),0,1)) | T29: =IF(B29="","",DATE(YEAR(B29),MONTH(B29),1)) | U29: =IF(OR(S29<>1,L29=""),"",COUNTIFS('LEADS'!$S$5:$S$504,1,'LEADS'!$L$5:$L$504,"<"&L29)+COUNTIFS($S$5:S29,1,$L$5:L29,L29))
A30: L-0026 | B30: 46091 | C30: Rowan Merriweather | D30: 555-0115 | E30: rowan.merriweather@example.com | F30: Nextdoor | G30: Deep Clean | H30: North Sampletown | I30: 650 | J30: Booked | K30: 46092 | O30: =IF(C30="","",IF(OR(J30="Booked",J30="Recurring Client"),"Booked",IF(J30="Lost/Declined","Lost","Open"))) | P30: =IF(C30="","",IF(S30=0,"—",IF(L30="","Set date",IF(L30<AsOf,"Overdue",IF(L30=AsOf,"Due today",IF(L30<=AsOf+SoonDays,"Due soon","Scheduled")))))) | Q30: =IF(C30="","",IF(B30="","",AsOf-B30)) | R30: =IF(C30="","",IF(O30<>"Booked","",IF(COUNTIF('CUSTOMERS'!$B$5:$B$404,C30)>0,"✓ In CUSTOMERS","Add to CUSTOMERS"))) | S30: =IF(C30="","",IF(OR(J30="Booked",J30="Recurring Client",J30="Lost/Declined"),0,1)) | T30: =IF(B30="","",DATE(YEAR(B30),MONTH(B30),1)) | U30: =IF(OR(S30<>1,L30=""),"",COUNTIFS('LEADS'!$S$5:$S$504,1,'LEADS'!$L$5:$L$504,"<"&L30)+COUNTIFS($S$5:S30,1,$L$5:L30,L30))
A31: L-0027 | B31: 46094 | C31: Logan Porter | D31: 555-0105 | E31: logan.porter@example.com | F31: Referral | G31: Deep Clean | H31: Lakeview (fictional) | I31: 530 | J31: Recurring Client | K31: 46095 | O31: =IF(C31="","",IF(OR(J31="Booked",J31="Recurring Client"),"Booked",IF(J31="Lost/Declined","Lost","Open"))) | P31: =IF(C31="","",IF(S31=0,"—",IF(L31="","Set date",IF(L31<AsOf,"Overdue",IF(L31=AsOf,"Due today",IF(L31<=AsOf+SoonDays,"Due soon","Scheduled")))))) | Q31: =IF(C31="","",IF(B31="","",AsOf-B31)) | R31: =IF(C31="","",IF(O31<>"Booked","",IF(COUNTIF('CUSTOMERS'!$B$5:$B$404,C31)>0,"✓ In CUSTOMERS","Add to CUSTOMERS"))) | S31: =IF(C31="","",IF(OR(J31="Booked",J31="Recurring Client",J31="Lost/Declined"),0,1)) | T31: =IF(B31="","",DATE(YEAR(B31),MONTH(B31),1)) | U31: =IF(OR(S31<>1,L31=""),"",COUNTIFS('LEADS'!$S$5:$S$504,1,'LEADS'!$L$5:$L$504,"<"&L31)+COUNTIFS($S$5:S31,1,$L$5:L31,L31))
A32: L-0028 | B32: 46098 | C32: Noel Collins | D32: 555-0107 | E32: noel.collins@example.com | F32: Facebook | G32: Deep Clean | H32: Lakeview (fictional) | I32: 595 | J32: Booked | K32: 46099 | O32: =IF(C32="","",IF(OR(J32="Booked",J32="Recurring Client"),"Booked",IF(J32="Lost/Declined","Lost","Open"))) | P32: =IF(C32="","",IF(S32=0,"—",IF(L32="","Set date",IF(L32<AsOf,"Overdue",IF(L32=AsOf,"Due today",IF(L32<=AsOf+SoonDays,"Due soon","Scheduled")))))) | Q32: =IF(C32="","",IF(B32="","",AsOf-B32)) | R32: =IF(C32="","",IF(O32<>"Booked","",IF(COUNTIF('CUSTOMERS'!$B$5:$B$404,C32)>0,"✓ In CUSTOMERS","Add to CUSTOMERS"))) | S32: =IF(C32="","",IF(OR(J32="Booked",J32="Recurring Client",J32="Lost/Declined"),0,1)) | T32: =IF(B32="","",DATE(YEAR(B32),MONTH(B32),1)) | U32: =IF(OR(S32<>1,L32=""),"",COUNTIFS('LEADS'!$S$5:$S$504,1,'LEADS'!$L$5:$L$504,"<"&L32)+COUNTIFS($S$5:S32,1,$L$5:L32,L32))
A33: L-0029 | B33: 46100 | C33: Devon Hartwell | D33: 555-0160 | E33: devon.hartwell@example.com | F33: Google Search | G33: Deep Clean | H33: Lakeview (fictional) | I33: 395 | J33: Lost/Declined | K33: 46103 | M33: No response | O33: =IF(C33="","",IF(OR(J33="Booked",J33="Recurring Client"),"Booked",IF(J33="Lost/Declined","Lost","Open"))) | P33: =IF(C33="","",IF(S33=0,"—",IF(L33="","Set date",IF(L33<AsOf,"Overdue",IF(L33=AsOf,"Due today",IF(L33<=AsOf+SoonDays,"Due soon","Scheduled")))))) | Q33: =IF(C33="","",IF(B33="","",AsOf-B33)) | R33: =IF(C33="","",IF(O33<>"Booked","",IF(COUNTIF('CUSTOMERS'!$B$5:$B$404,C33)>0,"✓ In CUSTOMERS","Add to CUSTOMERS"))) | S33: =IF(C33="","",IF(OR(J33="Booked",J33="Recurring Client",J33="Lost/Declined"),0,1)) | T33: =IF(B33="","",DATE(YEAR(B33),MONTH(B33),1)) | U33: =IF(OR(S33<>1,L33=""),"",COUNTIFS('LEADS'!$S$5:$S$504,1,'LEADS'!$L$5:$L$504,"<"&L33)+COUNTIFS($S$5:S33,1,$L$5:L33,L33))
A34: L-0030 | B34: 46105 | C34: Finley Quigley | D34: 555-0110 | E34: finley.quigley@example.com | F34: Google Search | G34: Deep Clean | H34: North Sampletown | I34: 250 | J34: Recurring Client | K34: 46106 | O34: =IF(C34="","",IF(OR(J34="Booked",J34="Recurring Client"),"Booked",IF(J34="Lost/Declined","Lost","Open"))) | P34: =IF(C34="","",IF(S34=0,"—",IF(L34="","Set date",IF(L34<AsOf,"Overdue",IF(L34=AsOf,"Due today",IF(L34<=AsOf+SoonDays,"Due soon","Scheduled")))))) | Q34: =IF(C34="","",IF(B34="","",AsOf-B34)) | R34: =IF(C34="","",IF(O34<>"Booked","",IF(COUNTIF('CUSTOMERS'!$B$5:$B$404,C34)>0,"✓ In CUSTOMERS","Add to CUSTOMERS"))) | S34: =IF(C34="","",IF(OR(J34="Booked",J34="Recurring Client",J34="Lost/Declined"),0,1)) | T34: =IF(B34="","",DATE(YEAR(B34),MONTH(B34),1)) | U34: =IF(OR(S34<>1,L34=""),"",COUNTIFS('LEADS'!$S$5:$S$504,1,'LEADS'!$L$5:$L$504,"<"&L34)+COUNTIFS($S$5:S34,1,$L$5:L34,L34))
A35: L-0031 | B35: 46105 | C35: Parker Holloway | D35: 555-0139 | E35: parker.holloway@example.com | F35: Google Business Profile | G35: Airbnb Turnover | H35: North Sampletown | J35: Lost/Declined | K35: 46109 | M35: Price | O35: =IF(C35="","",IF(OR(J35="Booked",J35="Recurring Client"),"Booked",IF(J35="Lost/Declined","Lost","Open"))) | P35: =IF(C35="","",IF(S35=0,"—",IF(L35="","Set date",IF(L35<AsOf,"Overdue",IF(L35=AsOf,"Due today",IF(L35<=AsOf+SoonDays,"Due soon","Scheduled")))))) | Q35: =IF(C35="","",IF(B35="","",AsOf-B35)) | R35: =IF(C35="","",IF(O35<>"Booked","",IF(COUNTIF('CUSTOMERS'!$B$5:$B$404,C35)>0,"✓ In CUSTOMERS","Add to CUSTOMERS"))) | S35: =IF(C35="","",IF(OR(J35="Booked",J35="Recurring Client",J35="Lost/Declined"),0,1)) | T35: =IF(B35="","",DATE(YEAR(B35),MONTH(B35),1)) | U35: =IF(OR(S35<>1,L35=""),"",COUNTIFS('LEADS'!$S$5:$S$504,1,'LEADS'!$L$5:$L$504,"<"&L35)+COUNTIFS($S$5:S35,1,$L$5:L35,L35))
A36: L-0032 | B36: 46111 | C36: Oakview Office Suites (sample) | D36: 555-0127 | E36: oakview.office.suites.(sample)@example.com | F36: Referral | G36: Commercial Clean | H36: North Sampletown | I36: 140 | J36: Recurring Client | K36: 46112 | O36: =IF(C36="","",IF(OR(J36="Booked",J36="Recurring Client"),"Booked",IF(J36="Lost/Declined","Lost","Open"))) | P36: =IF(C36="","",IF(S36=0,"—",IF(L36="","Set date",IF(L36<AsOf,"Overdue",IF(L36=AsOf,"Due today",IF(L36<=AsOf+SoonDays,"Due soon","Scheduled")))))) | Q36: =IF(C36="","",IF(B36="","",AsOf-B36)) | R36: =IF(C36="","",IF(O36<>"Booked","",IF(COUNTIF('CUSTOMERS'!$B$5:$B$404,C36)>0,"✓ In CUSTOMERS","Add to CUSTOMERS"))) | S36: =IF(C36="","",IF(OR(J36="Booked",J36="Recurring Client",J36="Lost/Declined"),0,1)) | T36: =IF(B36="","",DATE(YEAR(B36),MONTH(B36),1)) | U36: =IF(OR(S36<>1,L36=""),"",COUNTIFS('LEADS'!$S$5:$S$504,1,'LEADS'!$L$5:$L$504,"<"&L36)+COUNTIFS($S$5:S36,1,$L$5:L36,L36))
A37: L-0033 | B37: 46113 | C37: Kai Winslow | D37: 555-0152 | E37: kai.winslow@example.com | F37: Google Search | G37: Deep Clean | H37: Riverbend (fictional) | I37: 340 | J37: Lost/Declined | K37: 46117 | M37: No response | O37: =IF(C37="","",IF(OR(J37="Booked",J37="Recurring Client"),"Booked",IF(J37="Lost/Declined","Lost","Open"))) | P37: =IF(C37="","",IF(S37=0,"—",IF(L37="","Set date",IF(L37<AsOf,"Overdue",IF(L37=AsOf,"Due today",IF(L37<=AsOf+SoonDays,"Due soon","Scheduled")))))) | Q37: =IF(C37="","",IF(B37="","",AsOf-B37)) | R37: =IF(C37="","",IF(O37<>"Booked","",IF(COUNTIF('CUSTOMERS'!$B$5:$B$404,C37)>0,"✓ In CUSTOMERS","Add to CUSTOMERS"))) | S37: =IF(C37="","",IF(OR(J37="Booked",J37="Recurring Client",J37="Lost/Declined"),0,1)) | T37: =IF(B37="","",DATE(YEAR(B37),MONTH(B37),1)) | U37: =IF(OR(S37<>1,L37=""),"",COUNTIFS('LEADS'!$S$5:$S$504,1,'LEADS'!$L$5:$L$504,"<"&L37)+COUNTIFS($S$5:S37,1,$L$5:L37,L37))
A38: L-0034 | B38: 46117 | C38: Skyler Yardley | D38: 555-0122 | E38: skyler.yardley@example.com | F38: Nextdoor | G38: Deep Clean | H38: Sampletown | I38: 685 | J38: Booked | K38: 46118 | O38: =IF(C38="","",IF(OR(J38="Booked",J38="Recurring Client"),"Booked",IF(J38="Lost/Declined","Lost","Open"))) | P38: =IF(C38="","",IF(S38=0,"—",IF(L38="","Set date",IF(L38<AsOf,"Overdue",IF(L38=AsOf,"Due today",IF(L38<=AsOf+SoonDays,"Due soon","Scheduled")))))) | Q38: =IF(C38="","",IF(B38="","",AsOf-B38)) | R38: =IF(C38="","",IF(O38<>"Booked","",IF(COUNTIF('CUSTOMERS'!$B$5:$B$404,C38)>0,"✓ In CUSTOMERS","Add to CUSTOMERS"))) | S38: =IF(C38="","",IF(OR(J38="Booked",J38="Recurring Client",J38="Lost/Declined"),0,1)) | T38: =IF(B38="","",DATE(YEAR(B38),MONTH(B38),1)) | U38: =IF(OR(S38<>1,L38=""),"",COUNTIFS('LEADS'!$S$5:$S$504,1,'LEADS'!$L$5:$L$504,"<"&L38)+COUNTIFS($S$5:S38,1,$L$5:L38,L38))
A39: L-0035 | B39: 46129 | C39: Frankie Hayes | D39: 555-0138 | E39: frankie.hayes@example.com | F39: Website Form | G39: Deep Clean | H39: Old Mill District | J39: Lost/Declined | K39: 46132 | M39: Chose another company | O39: =IF(C39="","",IF(OR(J39="Booked",J39="Recurring Client"),"Booked",IF(J39="Lost/Declined","Lost","Open"))) | P39: =IF(C39="","",IF(S39=0,"—",IF(L39="","Set date",IF(L39<AsOf,"Overdue",IF(L39=AsOf,"Due today",IF(L39<=AsOf+SoonDays,"Due soon","Scheduled")))))) | Q39: =IF(C39="","",IF(B39="","",AsOf-B39)) | R39: =IF(C39="","",IF(O39<>"Booked","",IF(COUNTIF('CUSTOMERS'!$B$5:$B$404,C39)>0,"✓ In CUSTOMERS","Add to CUSTOMERS"))) | S39: =IF(C39="","",IF(OR(J39="Booked",J39="Recurring Client",J39="Lost/Declined"),0,1)) | T39: =IF(B39="","",DATE(YEAR(B39),MONTH(B39),1)) | U39: =IF(OR(S39<>1,L39=""),"",COUNTIFS('LEADS'!$S$5:$S$504,1,'LEADS'!$L$5:$L$504,"<"&L39)+COUNTIFS($S$5:S39,1,$L$5:L39,L39))
A40: L-0036 | B40: 46134 | C40: Parker Pembrook | D40: 555-0118 | E40: parker.pembrook@example.com | F40: Google Search | G40: Deep Clean | H40: Lakeview (fictional) | I40: 320 | J40: Booked | K40: 46135 | O40: =IF(C40="","",IF(OR(J40="Booked",J40="Recurring Client"),"Booked",IF(J40="Lost/Declined","Lost","Open"))) | P40: =IF(C40="","",IF(S40=0,"—",IF(L40="","Set date",IF(L40<AsOf,"Overdue",IF(L40=AsOf,"Due today",IF(L40<=AsOf+SoonDays,"Due soon","Scheduled")))))) | Q40: =IF(C40="","",IF(B40="","",AsOf-B40)) | R40: =IF(C40="","",IF(O40<>"Booked","",IF(COUNTIF('CUSTOMERS'!$B$5:$B$404,C40)>0,"✓ In CUSTOMERS","Add to CUSTOMERS"))) | S40: =IF(C40="","",IF(OR(J40="Booked",J40="Recurring Client",J40="Lost/Declined"),0,1)) | T40: =IF(B40="","",DATE(YEAR(B40),MONTH(B40),1)) | U40: =IF(OR(S40<>1,L40=""),"",COUNTIFS('LEADS'!$S$5:$S$504,1,'LEADS'!$L$5:$L$504,"<"&L40)+COUNTIFS($S$5:S40,1,$L$5:L40,L40))
...

Sheet CUSTOMERS
A1: CUSTOMERS
A2: Your customer list. History, lifetime revenue, balance due and the suggested next action fill in automatically from JOBS, RECURRING, REVIEWS and REFERRALS.
A3: ← Start Here | B3: Dashboard →
A4: Customer ID | B4: Customer Name (unique) | C4: Phone | D4: Email | E4: Customer Type | F4: Lead Source | G4: Preferred Contact | H4: Status | I4: Date Added | J4: Notes | K4: First Job ⚙ | L4: Last Job ⚙ | M4: Completed Jobs ⚙ | N4: Lifetime Revenue ⚙ | O4: Balance Due ⚙ | P4: Recurring Plan? ⚙ | Q4: Days Since Last Job ⚙ | R4: Suggested Next Action ⚙ | S4: Referrals Given ⚙
A5: C-001 | B5: Lane Ivers | C5: 555-0104 | D5: lane.ivers@example.com | E5: Residential | F5: Website Form | G5: Call | H5: Active | I5: 46042 | K5: =IF(B5="","",IF(_xlfn.MINIFS('JOBS'!$B$5:$B$1504,'JOBS'!$D$5:$D$1504,B5,'JOBS'!$O$5:$O$1504,"Completed")=0,"",_xlfn.MINIFS('JOBS'!$B$5:$B$1504,'JOBS'!$D$5:$D$1504,B5,'JOBS'!$O$5:$O$1504,"Completed"))) | L5: =IF(B5="","",IF(_xlfn.MAXIFS('JOBS'!$B$5:$B$1504,'JOBS'!$D$5:$D$1504,B5,'JOBS'!$O$5:$O$1504,"Completed")=0,"",_xlfn.MAXIFS('JOBS'!$B$5:$B$1504,'JOBS'!$D$5:$D$1504,B5,'JOBS'!$O$5:$O$1504,"Completed"))) | M5: =IF(B5="","",COUNTIFS('JOBS'!$D$5:$D$1504,B5,'JOBS'!$O$5:$O$1504,"Completed")) | N5: =IF(B5="","",SUMIFS('JOBS'!$L$5:$L$1504,'JOBS'!$D$5:$D$1504,B5,'JOBS'!$O$5:$O$1504,"Completed")) | O5: =IF(B5="","",SUMIFS('JOBS'!$U$5:$U$1504,'JOBS'!$D$5:$D$1504,B5)) | P5: =IF(B5="","",IF(COUNTIFS('RECURRING'!$B$5:$B$154,B5,'RECURRING'!$J$5:$J$154,"Active")>0,"Yes","No")) | Q5: =IF(L5="","",AsOf-L5) | R5: =IF(B5="","",IF(H5="Do not service","—",IF(O5>0.005,"Collect balance",IF(M5=0,"Book first job",IF(AND(P5="No",Q5>=ReactDays),"Reactivate",IF(COUNTIF('REVIEWS'!$A$5:$A$504,B5)=0,"Ask for review",IF(AND(P5="No",M5>=1),"Offer recurring plan","—"))))))) | S5: =IF(B5="","",COUNTIF('REFERRALS'!$B$5:$B$204,B5))
A6: C-002 | B6: Logan Porter | C6: 555-0105 | D6: logan.porter@example.com | E6: Residential | F6: Referral | G6: Text | H6: Active | I6: 46094 | K6: =IF(B6="","",IF(_xlfn.MINIFS('JOBS'!$B$5:$B$1504,'JOBS'!$D$5:$D$1504,B6,'JOBS'!$O$5:$O$1504,"Completed")=0,"",_xlfn.MINIFS('JOBS'!$B$5:$B$1504,'JOBS'!$D$5:$D$1504,B6,'JOBS'!$O$5:$O$1504,"Completed"))) | L6: =IF(B6="","",IF(_xlfn.MAXIFS('JOBS'!$B$5:$B$1504,'JOBS'!$D$5:$D$1504,B6,'JOBS'!$O$5:$O$1504,"Completed")=0,"",_xlfn.MAXIFS('JOBS'!$B$5:$B$1504,'JOBS'!$D$5:$D$1504,B6,'JOBS'!$O$5:$O$1504,"Completed"))) | M6: =IF(B6="","",COUNTIFS('JOBS'!$D$5:$D$1504,B6,'JOBS'!$O$5:$O$1504,"Completed")) | N6: =IF(B6="","",SUMIFS('JOBS'!$L$5:$L$1504,'JOBS'!$D$5:$D$1504,B6,'JOBS'!$O$5:$O$1504,"Completed")) | O6: =IF(B6="","",SUMIFS('JOBS'!$U$5:$U$1504,'JOBS'!$D$5:$D$1504,B6)) | P6: =IF(B6="","",IF(COUNTIFS('RECURRING'!$B$5:$B$154,B6,'RECURRING'!$J$5:$J$154,"Active")>0,"Yes","No")) | Q6: =IF(L6="","",AsOf-L6) | R6: =IF(B6="","",IF(H6="Do not service","—",IF(O6>0.005,"Collect balance",IF(M6=0,"Book first job",IF(AND(P6="No",Q6>=ReactDays),"Reactivate",IF(COUNTIF('REVIEWS'!$A$5:$A$504,B6)=0,"Ask for review",IF(AND(P6="No",M6>=1),"Offer recurring plan","—"))))))) | S6: =IF(B6="","",COUNTIF('REFERRALS'!$B$5:$B$204,B6))
A7: C-003 | B7: Devon Hayes | C7: 555-0106 | D7: devon.hayes@example.com | E7: Residential | F7: Google Business Profile | G7: Text | H7: Active | I7: 46161 | K7: =IF(B7="","",IF(_xlfn.MINIFS('JOBS'!$B$5:$B$1504,'JOBS'!$D$5:$D$1504,B7,'JOBS'!$O$5:$O$1504,"Completed")=0,"",_xlfn.MINIFS('JOBS'!$B$5:$B$1504,'JOBS'!$D$5:$D$1504,B7,'JOBS'!$O$5:$O$1504,"Completed"))) | L7: =IF(B7="","",IF(_xlfn.MAXIFS('JOBS'!$B$5:$B$1504,'JOBS'!$D$5:$D$1504,B7,'JOBS'!$O$5:$O$1504,"Completed")=0,"",_xlfn.MAXIFS('JOBS'!$B$5:$B$1504,'JOBS'!$D$5:$D$1504,B7,'JOBS'!$O$5:$O$1504,"Completed"))) | M7: =IF(B7="","",COUNTIFS('JOBS'!$D$5:$D$1504,B7,'JOBS'!$O$5:$O$1504,"Completed")) | N7: =IF(B7="","",SUMIFS('JOBS'!$L$5:$L$1504,'JOBS'!$D$5:$D$1504,B7,'JOBS'!$O$5:$O$1504,"Completed")) | O7: =IF(B7="","",SUMIFS('JOBS'!$U$5:$U$1504,'JOBS'!$D$5:$D$1504,B7)) | P7: =IF(B7="","",IF(COUNTIFS('RECURRING'!$B$5:$B$154,B7,'RECURRING'!$J$5:$J$154,"Active")>0,"Yes","No")) | Q7: =IF(L7="","",AsOf-L7) | R7: =IF(B7="","",IF(H7="Do not service","—",IF(O7>0.005,"Collect balance",IF(M7=0,"Book first job",IF(AND(P7="No",Q7>=ReactDays),"Reactivate",IF(COUNTIF('REVIEWS'!$A$5:$A$504,B7)=0,"Ask for review",IF(AND(P7="No",M7>=1),"Offer recurring plan","—"))))))) | S7: =IF(B7="","",COUNTIF('REFERRALS'!$B$5:$B$204,B7))
A8: C-004 | B8: Noel Collins | C8: 555-0107 | D8: noel.collins@example.com | E8: Residential | F8: Facebook | G8: Call | H8: Active | I8: 46098 | K8: =IF(B8="","",IF(_xlfn.MINIFS('JOBS'!$B$5:$B$1504,'JOBS'!$D$5:$D$1504,B8,'JOBS'!$O$5:$O$1504,"Completed")=0,"",_xlfn.MINIFS('JOBS'!$B$5:$B$1504,'JOBS'!$D$5:$D$1504,B8,'JOBS'!$O$5:$O$1504,"Completed"))) | L8: =IF(B8="","",IF(_xlfn.MAXIFS('JOBS'!$B$5:$B$1504,'JOBS'!$D$5:$D$1504,B8,'JOBS'!$O$5:$O$1504,"Completed")=0,"",_xlfn.MAXIFS('JOBS'!$B$5:$B$1504,'JOBS'!$D$5:$D$1504,B8,'JOBS'!$O$5:$O$1504,"Completed"))) | M8: =IF(B8="","",COUNTIFS('JOBS'!$D$5:$D$1504,B8,'JOBS'!$O$5:$O$1504,"Completed")) | N8: =IF(B8="","",SUMIFS('JOBS'!$L$5:$L$1504,'JOBS'!$D$5:$D$1504,B8,'JOBS'!$O$5:$O$1504,"Completed")) | O8: =IF(B8="","",SUMIFS('JOBS'!$U$5:$U$1504,'JOBS'!$D$5:$D$1504,B8)) | P8: =IF(B8="","",IF(COUNTIFS('RECURRING'!$B$5:$B$154,B8,'RECURRING'!$J$5:$J$154,"Active")>0,"Yes","No")) | Q8: =IF(L8="","",AsOf-L8) | R8: =IF(B8="","",IF(H8="Do not service","—",IF(O8>0.005,"Collect balance",IF(M8=0,"Book first job",IF(AND(P8="No",Q8>=ReactDays),"Reactivate",IF(COUNTIF('REVIEWS'!$A$5:$A$504,B8)=0,"Ask for review",IF(AND(P8="No",M8>=1),"Offer recurring plan","—"))))))) | S8: =IF(B8="","",COUNTIF('REFERRALS'!$B$5:$B$204,B8))
A9: C-005 | B9: Rowan Foxworth | C9: 555-0108 | D9: rowan.foxworth@example.com | E9: Residential | F9: Google Search | G9: Text | H9: Active | I9: 46089 | K9: =IF(B9="","",IF(_xlfn.MINIFS('JOBS'!$B$5:$B$1504,'JOBS'!$D$5:$D$1504,B9,'JOBS'!$O$5:$O$1504,"Completed")=0,"",_xlfn.MINIFS('JOBS'!$B$5:$B$1504,'JOBS'!$D$5:$D$1504,B9,'JOBS'!$O$5:$O$1504,"Completed"))) | L9: =IF(B9="","",IF(_xlfn.MAXIFS('JOBS'!$B$5:$B$1504,'JOBS'!$D$5:$D$1504,B9,'JOBS'!$O$5:$O$1504,"Completed")=0,"",_xlfn.MAXIFS('JOBS'!$B$5:$B$1504,'JOBS'!$D$5:$D$1504,B9,'JOBS'!$O$5:$O$1504,"Completed"))) | M9: =IF(B9="","",COUNTIFS('JOBS'!$D$5:$D$1504,B9,'JOBS'!$O$5:$O$1504,"Completed")) | N9: =IF(B9="","",SUMIFS('JOBS'!$L$5:$L$1504,'JOBS'!$D$5:$D$1504,B9,'JOBS'!$O$5:$O$1504,"Completed")) | O9: =IF(B9="","",SUMIFS('JOBS'!$U$5:$U$1504,'JOBS'!$D$5:$D$1504,B9)) | P9: =IF(B9="","",IF(COUNTIFS('RECURRING'!$B$5:$B$154,B9,'RECURRING'!$J$5:$J$154,"Active")>0,"Yes","No")) | Q9: =IF(L9="","",AsOf-L9) | R9: =IF(B9="","",IF(H9="Do not service","—",IF(O9>0.005,"Collect balance",IF(M9=0,"Book first job",IF(AND(P9="No",Q9>=ReactDays),"Reactivate",IF(COUNTIF('REVIEWS'!$A$5:$A$504,B9)=0,"Ask for review",IF(AND(P9="No",M9>=1),"Offer recurring plan","—"))))))) | S9: =IF(B9="","",COUNTIF('REFERRALS'!$B$5:$B$204,B9))
A10: C-006 | B10: Dana Collins | C10: 555-0109 | D10: dana.collins@example.com | E10: Residential | F10: Google Business Profile | G10: Text | H10: Active | I10: 46024 | K10: =IF(B10="","",IF(_xlfn.MINIFS('JOBS'!$B$5:$B$1504,'JOBS'!$D$5:$D$1504,B10,'JOBS'!$O$5:$O$1504,"Completed")=0,"",_xlfn.MINIFS('JOBS'!$B$5:$B$1504,'JOBS'!$D$5:$D$1504,B10,'JOBS'!$O$5:$O$1504,"Completed"))) | L10: =IF(B10="","",IF(_xlfn.MAXIFS('JOBS'!$B$5:$B$1504,'JOBS'!$D$5:$D$1504,B10,'JOBS'!$O$5:$O$1504,"Completed")=0,"",_xlfn.MAXIFS('JOBS'!$B$5:$B$1504,'JOBS'!$D$5:$D$1504,B10,'JOBS'!$O$5:$O$1504,"Completed"))) | M10: =IF(B10="","",COUNTIFS('JOBS'!$D$5:$D$1504,B10,'JOBS'!$O$5:$O$1504,"Completed")) | N10: =IF(B10="","",SUMIFS('JOBS'!$L$5:$L$1504,'JOBS'!$D$5:$D$1504,B10,'JOBS'!$O$5:$O$1504,"Completed")) | O10: =IF(B10="","",SUMIFS('JOBS'!$U$5:$U$1504,'JOBS'!$D$5:$D$1504,B10)) | P10: =IF(B10="","",IF(COUNTIFS('RECURRING'!$B$5:$B$154,B10,'RECURRING'!$J$5:$J$154,"Active")>0,"Yes","No")) | Q10: =IF(L10="","",AsOf-L10) | R10: =IF(B10="","",IF(H10="Do not service","—",IF(O10>0.005,"Collect balance",IF(M10=0,"Book first job",IF(AND(P10="No",Q10>=ReactDays),"Reactivate",IF(COUNTIF('REVIEWS'!$A$5:$A$504,B10)=0,"Ask for review",IF(AND(P10="No",M10>=1),"Offer recurring plan","—"))))))) | S10: =IF(B10="","",COUNTIF('REFERRALS'!$B$5:$B$204,B10))
A11: C-007 | B11: Finley Quigley | C11: 555-0110 | D11: finley.quigley@example.com | E11: Residential | F11: Google Search | G11: Call | H11: Active | I11: 46105 | K11: =IF(B11="","",IF(_xlfn.MINIFS('JOBS'!$B$5:$B$1504,'JOBS'!$D$5:$D$1504,B11,'JOBS'!$O$5:$O$1504,"Completed")=0,"",_xlfn.MINIFS('JOBS'!$B$5:$B$1504,'JOBS'!$D$5:$D$1504,B11,'JOBS'!$O$5:$O$1504,"Completed"))) | L11: =IF(B11="","",IF(_xlfn.MAXIFS('JOBS'!$B$5:$B$1504,'JOBS'!$D$5:$D$1504,B11,'JOBS'!$O$5:$O$1504,"Completed")=0,"",_xlfn.MAXIFS('JOBS'!$B$5:$B$1504,'JOBS'!$D$5:$D$1504,B11,'JOBS'!$O$5:$O$1504,"Completed"))) | M11: =IF(B11="","",COUNTIFS('JOBS'!$D$5:$D$1504,B11,'JOBS'!$O$5:$O$1504,"Completed")) | N11: =IF(B11="","",SUMIFS('JOBS'!$L$5:$L$1504,'JOBS'!$D$5:$D$1504,B11,'JOBS'!$O$5:$O$1504,"Completed")) | O11: =IF(B11="","",SUMIFS('JOBS'!$U$5:$U$1504,'JOBS'!$D$5:$D$1504,B11)) | P11: =IF(B11="","",IF(COUNTIFS('RECURRING'!$B$5:$B$154,B11,'RECURRING'!$J$5:$J$154,"Active")>0,"Yes","No")) | Q11: =IF(L11="","",AsOf-L11) | R11: =IF(B11="","",IF(H11="Do not service","—",IF(O11>0.005,"Collect balance",IF(M11=0,"Book first job",IF(AND(P11="No",Q11>=ReactDays),"Reactivate",IF(COUNTIF('REVIEWS'!$A$5:$A$504,B11)=0,"Ask for review",IF(AND(P11="No",M11>=1),"Offer recurring plan","—"))))))) | S11: =IF(B11="","",COUNTIF('REFERRALS'!$B$5:$B$204,B11))
A12: C-008 | B12: Dana Ivers | C12: 555-0111 | D12: dana.ivers@example.com | E12: Residential | F12: Google Business Profile | G12: Text | H12: Active | I12: 46147 | K12: =IF(B12="","",IF(_xlfn.MINIFS('JOBS'!$B$5:$B$1504,'JOBS'!$D$5:$D$1504,B12,'JOBS'!$O$5:$O$1504,"Completed")=0,"",_xlfn.MINIFS('JOBS'!$B$5:$B$1504,'JOBS'!$D$5:$D$1504,B12,'JOBS'!$O$5:$O$1504,"Completed"))) | L12: =IF(B12="","",IF(_xlfn.MAXIFS('JOBS'!$B$5:$B$1504,'JOBS'!$D$5:$D$1504,B12,'JOBS'!$O$5:$O$1504,"Completed")=0,"",_xlfn.MAXIFS('JOBS'!$B$5:$B$1504,'JOBS'!$D$5:$D$1504,B12,'JOBS'!$O$5:$O$1504,"Completed"))) | M12: =IF(B12="","",COUNTIFS('JOBS'!$D$5:$D$1504,B12,'JOBS'!$O$5:$O$1504,"Completed")) | N12: =IF(B12="","",SUMIFS('JOBS'!$L$5:$L$1504,'JOBS'!$D$5:$D$1504,B12,'JOBS'!$O$5:$O$1504,"Completed")) | O12: =IF(B12="","",SUMIFS('JOBS'!$U$5:$U$1504,'JOBS'!$D$5:$D$1504,B12)) | P12: =IF(B12="","",IF(COUNTIFS('RECURRING'!$B$5:$B$154,B12,'RECURRING'!$J$5:$J$154,"Active")>0,"Yes","No")) | Q12: =IF(L12="","",AsOf-L12) | R12: =IF(B12="","",IF(H12="Do not service","—",IF(O12>0.005,"Collect balance",IF(M12=0,"Book first job",IF(AND(P12="No",Q12>=ReactDays),"Reactivate",IF(COUNTIF('REVIEWS'!$A$5:$A$504,B12)=0,"Ask for review",IF(AND(P12="No",M12>=1),"Offer recurring plan","—"))))))) | S12: =IF(B12="","",COUNTIF('REFERRALS'!$B$5:$B$204,B12))
A13: C-009 | B13: Taylor Quigley | C13: 555-0112 | D13: taylor.quigley@example.com | E13: Residential | F13: Flyer / Door Hanger | G13: Text | H13: Active | I13: 46036 | K13: =IF(B13="","",IF(_xlfn.MINIFS('JOBS'!$B$5:$B$1504,'JOBS'!$D$5:$D$1504,B13,'JOBS'!$O$5:$O$1504,"Completed")=0,"",_xlfn.MINIFS('JOBS'!$B$5:$B$1504,'JOBS'!$D$5:$D$1504,B13,'JOBS'!$O$5:$O$1504,"Completed"))) | L13: =IF(B13="","",IF(_xlfn.MAXIFS('JOBS'!$B$5:$B$1504,'JOBS'!$D$5:$D$1504,B13,'JOBS'!$O$5:$O$1504,"Completed")=0,"",_xlfn.MAXIFS('JOBS'!$B$5:$B$1504,'JOBS'!$D$5:$D$1504,B13,'JOBS'!$O$5:$O$1504,"Completed"))) | M13: =IF(B13="","",COUNTIFS('JOBS'!$D$5:$D$1504,B13,'JOBS'!$O$5:$O$1504,"Completed")) | N13: =IF(B13="","",SUMIFS('JOBS'!$L$5:$L$1504,'JOBS'!$D$5:$D$1504,B13,'JOBS'!$O$5:$O$1504,"Completed")) | O13: =IF(B13="","",SUMIFS('JOBS'!$U$5:$U$1504,'JOBS'!$D$5:$D$1504,B13)) | P13: =IF(B13="","",IF(COUNTIFS('RECURRING'!$B$5:$B$154,B13,'RECURRING'!$J$5:$J$154,"Active")>0,"Yes","No")) | Q13: =IF(L13="","",AsOf-L13) | R13: =IF(B13="","",IF(H13="Do not service","—",IF(O13>0.005,"Collect balance",IF(M13=0,"Book first job",IF(AND(P13="No",Q13>=ReactDays),"Reactivate",IF(COUNTIF('REVIEWS'!$A$5:$A$504,B13)=0,"Ask for review",IF(AND(P13="No",M13>=1),"Offer recurring plan","—"))))))) | S13: =IF(B13="","",COUNTIF('REFERRALS'!$B$5:$B$204,B13))
A14: C-010 | B14: Lane Northcott | C14: 555-0113 | D14: lane.northcott@example.com | E14: Residential | F14: Google Business Profile | G14: Email | H14: Active | I14: 46030 | K14: =IF(B14="","",IF(_xlfn.MINIFS('JOBS'!$B$5:$B$1504,'JOBS'!$D$5:$D$1504,B14,'JOBS'!$O$5:$O$1504,"Completed")=0,"",_xlfn.MINIFS('JOBS'!$B$5:$B$1504,'JOBS'!$D$5:$D$1504,B14,'JOBS'!$O$5:$O$1504,"Completed"))) | L14: =IF(B14="","",IF(_xlfn.MAXIFS('JOBS'!$B$5:$B$1504,'JOBS'!$D$5:$D$1504,B14,'JOBS'!$O$5:$O$1504,"Completed")=0,"",_xlfn.MAXIFS('JOBS'!$B$5:$B$1504,'JOBS'!$D$5:$D$1504,B14,'JOBS'!$O$5:$O$1504,"Completed"))) | M14: =IF(B14="","",COUNTIFS('JOBS'!$D$5:$D$1504,B14,'JOBS'!$O$5:$O$1504,"Completed")) | N14: =IF(B14="","",SUMIFS('JOBS'!$L$5:$L$1504,'JOBS'!$D$5:$D$1504,B14,'JOBS'!$O$5:$O$1504,"Completed")) | O14: =IF(B14="","",SUMIFS('JOBS'!$U$5:$U$1504,'JOBS'!$D$5:$D$1504,B14)) | P14: =IF(B14="","",IF(COUNTIFS('RECURRING'!$B$5:$B$154,B14,'RECURRING'!$J$5:$J$154,"Active")>0,"Yes","No")) | Q14: =IF(L14="","",AsOf-L14) | R14: =IF(B14="","",IF(H14="Do not service","—",IF(O14>0.005,"Collect balance",IF(M14=0,"Book first job",IF(AND(P14="No",Q14>=ReactDays),"Reactivate",IF(COUNTIF('REVIEWS'!$A$5:$A$504,B14)=0,"Ask for review",IF(AND(P14="No",M14>=1),"Offer recurring plan","—"))))))) | S14: =IF(B14="","",COUNTIF('REFERRALS'!$B$5:$B$204,B14))
